Workbook

Sheet Standings
C2: Name | D2: Total
C3: Gunter | D3: ='Total Points'!C24 -> 42 | E3: x
C4: Uncle Joe | D4: ='Total Points'!E24 -> 41.5 | E4: x
C5: Tbone | D5: ='Total Points'!L24 -> 39.9 | E5: x
C6: Tim | D6: ='Total Points'!B24 -> 38.4 | E6: x
C7: Ben | D7: ='Total Points'!J24 -> 37.2 | E7: x
C8: Vince | D8: ='Total Points'!P24 -> 34.9 | E8: x
C9: Andrew | D9: ='Total Points'!K24 -> 32.1 | E9: x
C10: Harvey | D10: ='Total Points'!U24 -> 32 | E10: x
C11: Tophe | D11: ='Total Points'!R24 -> 28.6 | E11: x
C12: Matt F | D12: ='Total Points'!O24 -> 27.6 | E12: x
C13: Eli | D13: ='Total Points'!F24 -> 26.8 | E13: x
C14: Pete | D14: ='Total Points'!S24 -> 26.3 | E14: x
C15: Tom K | D15: ='Total Points'!D24 -> 26.05 | E15: x
C16: Tommy | D16: ='Total Points'!I24 -> 26 | E16: x
C17: Uncle Mike | D17: ='Total Points'!Q24 -> 25.6 | E17: x
C18: Dan | D18: ='Total Points'!H24 -> 24.25 | E18: x
C19: Oaks | D19: ='Total Points'!N24 -> 22.4
C20: Matt D | D20: ='Total Points'!G24 -> 21.9 | E20: x
C21: Trock | D21: ='Total Points'!M24 -> 21.6 | E21: x
C22: Jimmy D | D22: ='Total Points'!T24 -> 20.5

Sheet Golf
A1: Gettysburg National Golf Club
A2: Friday, August 18th 2022
C4: 1 | D4: 2 | E4: 3 | F4: 4 | G4: 5 | H4: 6 | I4: 7 | J4: 8 | K4: 9 | L4: In | N4: 10 | O4: 11 | P4: 12 | Q4: 13 | R4: 14 | S4: 15 | T4: 16 | U4: 17 | V4: 18 | W4: In | X4: Out
A5: White Tees | B5: Yards | C5: 485 | D5: 380 | E5: 145 | F5: 562 | G5: 184 | H5: 322 | I5: 385 | J5: 200 | K5: 471 | L5: =SUM(C5:K5) -> 3134 | M5: Yards | N5: 373 | O5: 193 | P5: 524 | Q5: 402 | R5: 405 | S5: 167 | T5: 425 | U5: 537 | V5: 170 | W5: =SUM(N5:V5) -> 3196 | X5: Total
C6: 4 | D6: 4 | E6: 3 | F6: 4 | G6: 4 | H6: 4 | I6: 3 | J6: 5 | K6: 4 | L6: =SUM(C6:K6) -> 35 | M6: Par | N6: 4 | O6: 4 | P6: 3 | Q6: 4 | R6: 5 | S6: 4 | T6: 4 | U6: 3 | V6: 5 | W6: =SUM(N6:V6) -> 36
B7: Handicap | C7: 6 | D7: 10 | E7: 18 | F7: 12 | G7: 8 | H7: 2 | I7: 16 | J7: 4 | K7: 14 | M7: Handicap | N7: 11 | O7: 5 | P7: 15 | Q7: 7 | R7: 9 | S7: 13 | T7: 1 | U7: 17 | V7: 3
A8: Eli | B8: Gross Score | C8: 4 | D8: 4 | E8: 4 | F8: 4 | G8: 4 | H8: 6 | I8: 4 | J8: 8 | K8: 6 | L8: =SUM(C8:K8) -> 44 | M8: Gross Score | N8: 4 | O8: 4 | P8: 3 | Q8: 5 | R8: 6 | S8: 4 | T8: 5 | U8: 3 | V8: 5 | W8: =SUM(N8:V8) -> 39 | X8: =L8+W8 -> 83
A9: 2 | B9: Handicap | H9: -1 | L9: =SUM(C9:K9) -> -1 | M9: Handicap | T9: -1 | W9: =SUM(N9:V9) -> -1 | X9: =L9+W9 -> -2
B10: Net Score | C10: =SUM(C8:C9) -> 4 | D10: =SUM(D8:D9) -> 4 | E10: =SUM(E8:E9) -> 4 | F10: =SUM(F8:F9) -> 4 | G10: =SUM(G8:G9) -> 4 | H10: =SUM(H8:H9) -> 5 | I10: =SUM(I8:I9) -> 4 | J10: =SUM(J8:J9) -> 8 | K10: =SUM(K8:K9) -> 6 | L10: =SUM(C10:K10) -> 43 | M10: Net Score | N10: =SUM(N8:N9) -> 4 | O10: =SUM(O8:O9) -> 4 | P10: =SUM(P8:P9) -> 3 | Q10: =SUM(Q8:Q9) -> 5 | R10: =SUM(R8:R9) -> 6 | S10: =SUM(S8:S9) -> 4 | T10: =SUM(T8:T9) -> 4 | U10: =SUM(U8:U9) -> 3 | V10: =SUM(V8:V9) -> 5 | W10: =SUM(N10:V10) -> 38 | X10: =L10+W10 -> 81
B11: Points | C11: =IF(C10=0,0,IF(C10-C6=-3,3,IF(C10-C6=-2,1.5,IF(C10-C6=-1,0.8,IF(C10-C6=0,0.4,IF(C10-C6=1,0,IF(C10-C6<=2>15,0,_xludf.IF))))))) -> 0.4 | D11: =IF(D10=0,0,IF(D10-D6=-3,3,IF(D10-D6=-2,1.5,IF(D10-D6=-1,0.8,IF(D10-D6=0,0.4,IF(D10-D6=1,0,IF(D10-D6<=2>15,0,_xludf.IF))))))) -> 0.4 | E11: =IF(E10=0,0,IF(E10-E6=-3,3,IF(E10-E6=-2,1.5,IF(E10-E6=-1,0.8,IF(E10-E6=0,0.4,IF(E10-E6=1,0,IF(E10-E6<=2>15,0,_xludf.IF))))))) -> 0 | F11: =IF(F10=0,0,IF(F10-F6=-3,3,IF(F10-F6=-2,1.5,IF(F10-F6=-1,0.8,IF(F10-F6=0,0.4,IF(F10-F6=1,0,IF(F10-F6<=2>15,0,_xludf.IF))))))) -> 0.4 | G11: =IF(G10=0,0,IF(G10-G6=-3,3,IF(G10-G6=-2,1.5,IF(G10-G6=-1,0.8,IF(G10-G6=0,0.4,IF(G10-G6=1,0,IF(G10-G6<=2>15,0,_xludf.IF))))))) -> 0.4 | H11: =IF(H10=0,0,IF(H10-H6=-3,3,IF(H10-H6=-2,1.5,IF(H10-H6=-1,0.8,IF(H10-H6=0,0.4,IF(H10-H6=1,0,IF(H10-H6<=2>15,0,_xludf.IF))))))) -> 0 | I11: =IF(I10=0,0,IF(I10-I6=-3,3,IF(I10-I6=-2,1.5,IF(I10-I6=-1,0.8,IF(I10-I6=0,0.4,IF(I10-I6=1,0,IF(I10-I6<=2>15,0,_xludf.IF))))))) -> 0 | J11: =IF(J10=0,0,IF(J10-J6=-3,3,IF(J10-J6=-2,1.5,IF(J10-J6=-1,0.8,IF(J10-J6=0,0.4,IF(J10-J6=1,0,IF(J10-J6<=2>15,0,_xludf.IF))))))) -> 0 | K11: =IF(K10=0,0,IF(K10-K6=-3,3,IF(K10-K6=-2,1.5,IF(K10-K6=-1,0.8,IF(K10-K6=0,0.4,IF(K10-K6=1,0,IF(K10-K6<=2>15,0,_xludf.IF))))))) -> 0 | L11: =SUM(C11:K11) -> 1.6 | M11: Points | N11: =IF(N10=0,0,IF(N10-N6=-3,3,IF(N10-N6=-2,1.5,IF(N10-N6=-1,0.8,IF(N10-N6=0,0.4,IF(N10-N6=1,0,IF(N10-N6<=2>15,0,_xludf.IF))))))) -> 0.4 | O11: =IF(O10=0,0,IF(O10-O6=-3,3,IF(O10-O6=-2,1.5,IF(O10-O6=-1,0.8,IF(O10-O6=0,0.4,IF(O10-O6=1,0,IF(O10-O6<=2>15,0,_xludf.IF))))))) -> 0.4 | P11: =IF(P10=0,0,IF(P10-P6=-3,3,IF(P10-P6=-2,1.5,IF(P10-P6=-1,0.8,IF(P10-P6=0,0.4,IF(P10-P6=1,0,IF(P10-P6<=2>15,0,_xludf.IF))))))) -> 0.4 | Q11: =IF(Q10=0,0,IF(Q10-Q6=-3,3,IF(Q10-Q6=-2,1.5,IF(Q10-Q6=-1,0.8,IF(Q10-Q6=0,0.4,IF(Q10-Q6=1,0,IF(Q10-Q6<=2>15,0,_xludf.IF))))))) -> 0 | R11: =IF(R10=0,0,IF(R10-R6=-3,3,IF(R10-R6=-2,1.5,IF(R10-R6=-1,0.8,IF(R10-R6=0,0.4,IF(R10-R6=1,0,IF(R10-R6<=2>15,0,_xludf.IF))))))) -> 0 | S11: =IF(S10=0,0,IF(S10-S6=-3,3,IF(S10-S6=-2,1.5,IF(S10-S6=-1,0.8,IF(S10-S6=0,0.4,IF(S10-S6=1,0,IF(S10-S6<=2>15,0,_xludf.IF))))))) -> 0.4 | T11: =IF(T10=0,0,IF(T10-T6=-3,3,IF(T10-T6=-2,1.5,IF(T10-T6=-1,0.8,IF(T10-T6=0,0.4,IF(T10-T6=1,0,IF(T10-T6<=2>15,0,_xludf.IF))))))) -> 0.4 | U11: =IF(U10=0,0,IF(U10-U6=-3,3,IF(U10-U6=-2,1.5,IF(U10-U6=-1,0.8,IF(U10-U6=0,0.4,IF(U10-U6=1,0,IF(U10-U6<=2>15,0,_xludf.IF))))))) -> 0.4 | V11: =IF(V10=0,0,IF(V10-V6=-3,3,IF(V10-V6=-2,1.5,IF(V10-V6=-1,0.8,IF(V10-V6=0,0.4,IF(V10-V6=1,0,IF(V10-V6<=2>15,0,_xludf.IF))))))) -> 0.4 | W11: =SUM(N11:V11) -> 2.8 | X11: =L11+W11 -> 4.4
A12: Matt | B12: Gross Score | C12: 5 | D12: 6 | E12: 4 | F12: 4 | G12: 6 | H12: 5 | I12: 4 | J12: 6 | K12: 6 | L12: =SUM(C12:K12) -> 46 | M12: Gross Score | N12: 7 | O12: 6 | P12: 3 | Q12: 4 | R12: 8 | S12: 6 | T12: 5 | U12: 5 | V12: 5 | W12: =SUM(N12:V12) -> 49 | X12: =L12+W12 -> 95
A13: 5 | B13: Handicap | H13: -1 | J13: -1 | L13: =SUM(C13:K13) -> -2 | M13: Handicap | O13: -1 | T13: -1 | V13: -1 | W13: =SUM(N13:V13) -> -3 | X13: =L13+W13 -> -5
B14: Net Score | C14: =SUM(C12:C13) -> 5 | D14: =SUM(D12:D13) -> 6 | E14: =SUM(E12:E13) -> 4 | F14: =SUM(F12:F13) -> 4 | G14: =SUM(G12:G13) -> 6 | H14: =SUM(H12:H13) -> 4 | I14: =SUM(I12:I13) -> 4 | J14: =SUM(J12:J13) -> 5 | K14: =SUM(K12:K13) -> 6 | L14: =SUM(C14:K14) -> 44 | M14: Net Score | N14: =SUM(N12:N13) -> 7 | O14: =SUM(O12:O13) -> 5 | P14: =SUM(P12:P13) -> 3 | Q14: =SUM(Q12:Q13) -> 4 | R14: =SUM(R12:R13) -> 8 | S14: =SUM(S12:S13) -> 6 | T14: =SUM(T12:T13) -> 4 | U14: =SUM(U12:U13) -> 5 | V14: =SUM(V12:V13) -> 4 | W14: =SUM(N14:V14) -> 46 | X14: =L14+W14 -> 90
B15: Points | C15: =IF(C14=0,0,IF(C14-C6=-3,3,IF(C14-C6=-2,1.5,IF(C14-C6=-1,0.8,IF(C14-C6=0,0.4,IF(C14-C6=1,0,IF(C14-C6<=2>15,0,_xludf.IF))))))) -> 0 | D15: =IF(D14=0,0,IF(D14-D6=-3,3,IF(D14-D6=-2,1.5,IF(D14-D6=-1,0.8,IF(D14-D6=0,0.4,IF(D14-D6=1,0,IF(D14-D6<=2>15,0,_xludf.IF))))))) -> 0 | E15: =IF(E14=0,0,IF(E14-E6=-3,3,IF(E14-E6=-2,1.5,IF(E14-E6=-1,0.8,IF(E14-E6=0,0.4,IF(E14-E6=1,0,IF(E14-E6<=2>15,0,_xludf.IF))))))) -> 0 | F15: =IF(F14=0,0,IF(F14-F6=-3,3,IF(F14-F6=-2,1.5,IF(F14-F6=-1,0.8,IF(F14-F6=0,0.4,IF(F14-F6=1,0,IF(F14-F6<=2>15,0,_xludf.IF))))))) -> 0.4 | G15: =IF(G14=0,0,IF(G14-G6=-3,3,IF(G14-G6=-2,1.5,IF(G14-G6=-1,0.8,IF(G14-G6=0,0.4,IF(G14-G6=1,0,IF(G14-G6<=2>15,0,_xludf.IF))))))) -> 0 | H15: =IF(H14=0,0,IF(H14-H6=-3,3,IF(H14-H6=-2,1.5,IF(H14-H6=-1,0.8,IF(H14-H6=0,0.4,IF(H14-H6=1,0,IF(H14-H6<=2>15,0,_xludf.IF))))))) -> 0.4 | I15: =IF(I14=0,0,IF(I14-I6=-3,3,IF(I14-I6=-2,1.5,IF(I14-I6=-1,0.8,IF(I14-I6=0,0.4,IF(I14-I6=1,0,IF(I14-I6<=2>15,0,_xludf.IF))))))) -> 0 | J15: =IF(J14=0,0,IF(J14-J6=-3,3,IF(J14-J6=-2,1.5,IF(J14-J6=-1,0.8,IF(J14-J6=0,0.4,IF(J14-J6=1,0,IF(J14-J6<=2>15,0,_xludf.IF))))))) -> 0.4 | K15: =IF(K14=0,0,IF(K14-K6=-3,3,IF(K14-K6=-2,1.5,IF(K14-K6=-1,0.8,IF(K14-K6=0,0.4,IF(K14-K6=1,0,IF(K14-K6<=2>15,0,_xludf.IF))))))) -> 0 | L15: =SUM(C15:K15) -> 1.2 | M15: Points | N15: =IF(N14=0,0,IF(N14-N6=-3,3,IF(N14-N6=-2,1.5,IF(N14-N6=-1,0.8,IF(N14-N6=0,0.4,IF(N14-N6=1,0,IF(N14-N6<=2>15,0,_xludf.IF))))))) -> 0 | O15: =IF(O14=0,0,IF(O14-O6=-3,3,IF(O14-O6=-2,1.5,IF(O14-O6=-1,0.8,IF(O14-O6=0,0.4,IF(O14-O6=1,0,IF(O14-O6<=2>15,0,_xludf.IF))))))) -> 0 | P15: =IF(P14=0,0,IF(P14-P6=-3,3,IF(P14-P6=-2,1.5,IF(P14-P6=-1,0.8,IF(P14-P6=0,0.4,IF(P14-P6=1,0,IF(P14-P6<=2>15,0,_xludf.IF))))))) -> 0.4 | Q15: =IF(Q14=0,0,IF(Q14-Q6=-3,3,IF(Q14-Q6=-2,1.5,IF(Q14-Q6=-1,0.8,IF(Q14-Q6=0,0.4,IF(Q14-Q6=1,0,IF(Q14-Q6<=2>15,0,_xludf.IF))))))) -> 0.4 | R15: =IF(R14=0,0,IF(R14-R6=-3,3,IF(R14-R6=-2,1.5,IF(R14-R6=-1,0.8,IF(R14-R6=0,0.4,IF(R14-R6=1,0,IF(R14-R6<=2>15,0,_xludf.IF))))))) -> 0 | S15: =IF(S14=0,0,IF(S14-S6=-3,3,IF(S14-S6=-2,1.5,IF(S14-S6=-1,0.8,IF(S14-S6=0,0.4,IF(S14-S6=1,0,IF(S14-S6<=2>15,0,_xludf.IF))))))) -> 0 | T15: =IF(T14=0,0,IF(T14-T6=-3,3,IF(T14-T6=-2,1.5,IF(T14-T6=-1,0.8,IF(T14-T6=0,0.4,IF(T14-T6=1,0,IF(T14-T6<=2>15,0,_xludf.IF))))))) -> 0.4 | U15: =IF(U14=0,0,IF(U14-U6=-3,3,IF(U14-U6=-2,1.5,IF(U14-U6=-1,0.8,IF(U14-U6=0,0.4,IF(U14-U6=1,0,IF(U14-U6<=2>15,0,_xludf.IF))))))) -> 0 | V15: =IF(V14=0,0,IF(V14-V6=-3,3,IF(V14-V6=-2,1.5,IF(V14-V6=-1,0.8,IF(V14-V6=0,0.4,IF(V14-V6=1,0,IF(V14-V6<=2>15,0,_xludf.IF))))))) -> 0.8 | W15: =SUM(N15:V15) -> 2 | X15: =L15+W15 -> 3.2
A16: Dan | B16: Gross Score | C16: 5 | D16: 5 | E16: 6 | F16: 5 | G16: 5 | H16: 5 | I16: 5 | J16: 5 | K16: 4 | L16: =SUM(C16:K16) -> 45 | M16: Gross Score | N16: 5 | O16: 5 | P16: 4 | Q16: 6 | R16: 8 | S16: 8 | T16: 7 | U16: 3 | V16: 8 | W16: =SUM(N16:V16) -> 54 | X16: =L16+W16 -> 99
A17: 12 | B17: Handicap | C17: -1 | D17: -1 | F17: -1 | G17: -1 | H17: -1 | J17: -1 | L17: =SUM(C17:K17) -> -6 | M17: Handicap | N17: -1 | O17: -1 | Q17: -1 | R17: -1 | T17: -1 | V17: -1 | W17: =SUM(N17:V17) -> -6 | X17: =L17+W17 -> -12
B18: Net Score | C18: =SUM(C16:C17) -> 4 | D18: =SUM(D16:D17) -> 4 | E18: =SUM(E16:E17) -> 6 | F18: =SUM(F16:F17) -> 4 | G18: =SUM(G16:G17) -> 4 | H18: =SUM(H16:H17) -> 4 | I18: =SUM(I16:I17) -> 5 | J18: =SUM(J16:J17) -> 4 | K18: =SUM(K16:K17) -> 4 | L18: =SUM(C18:K18) -> 39 | M18: Net Score | N18: =SUM(N16:N17) -> 4 | O18: =SUM(O16:O17) -> 4 | P18: =SUM(P16:P17) -> 4 | Q18: =SUM(Q16:Q17) -> 5 | R18: =SUM(R16:R17) -> 7 | S18: =SUM(S16:S17) -> 8 | T18: =SUM(T16:T17) -> 6 | U18: =SUM(U16:U17) -> 3 | V18: =SUM(V16:V17) -> 7 | W18: =SUM(N18:V18) -> 48 | X18: =L18+W18 -> 87
B19: Points | C19: =IF(C18=0,0,IF(C18-C6=-3,3,IF(C18-C6=-2,1.5,IF(C18-C6=-1,0.8,IF(C18-C6=0,0.4,IF(C18-C6=1,0,IF(C18-C6<=2>15,0,_xludf.IF))))))) -> 0.4 | D19: =IF(D18=0,0,IF(D18-D6=-3,3,IF(D18-D6=-2,1.5,IF(D18-D6=-1,0.8,IF(D18-D6=0,0.4,IF(D18-D6=1,0,IF(D18-D6<=2>15,0,_xludf.IF))))))) -> 0.4 | E19: =IF(E18=0,0,IF(E18-E6=-3,3,IF(E18-E6=-2,1.5,IF(E18-E6=-1,0.8,IF(E18-E6=0,0.4,IF(E18-E6=1,0,IF(E18-E6<=2>15,0,_xludf.IF))))))) -> 0 | F19: =IF(F18=0,0,IF(F18-F6=-3,3,IF(F18-F6=-2,1.5,IF(F18-F6=-1,0.8,IF(F18-F6=0,0.4,IF(F18-F6=1,0,IF(F18-F6<=2>15,0,_xludf.IF))))))) -> 0.4 | G19: =IF(G18=0,0,IF(G18-G6=-3,3,IF(G18-G6=-2,1.5,IF(G18-G6=-1,0.8,IF(G18-G6=0,0.4,IF(G18-G6=1,0,IF(G18-G6<=2>15,0,_xludf.IF))))))) -> 0.4 | H19: =IF(H18=0,0,IF(H18-H6=-3,3,IF(H18-H6=-2,1.5,IF(H18-H6=-1,0.8,IF(H18-H6=0,0.4,IF(H18-H6=1,0,IF(H18-H6<=2>15,0,_xludf.IF))))))) -> 0.4 | I19: =IF(I18=0,0,IF(I18-I6=-3,3,IF(I18-I6=-2,1.5,IF(I18-I6=-1,0.8,IF(I18-I6=0,0.4,IF(I18-I6=1,0,IF(I18-I6<=2>15,0,_xludf.IF))))))) -> 0 | J19: =IF(J18=0,0,IF(J18-J6=-3,3,IF(J18-J6=-2,1.5,IF(J18-J6=-1,0.8,IF(J18-J6=0,0.4,IF(J18-J6=1,0,IF(J18-J6<=2>15,0,_xludf.IF))))))) -> 0.8 | K19: =IF(K18=0,0,IF(K18-K6=-3,3,IF(K18-K6=-2,1.5,IF(K18-K6=-1,0.8,IF(K18-K6=0,0.4,IF(K18-K6=1,0,IF(K18-K6<=2>15,0,_xludf.IF))))))) -> 0.4 | L19: =SUM(C19:K19) -> 3.2 | M19: Points | N19: =IF(N18=0,0,IF(N18-N6=-3,3,IF(N18-N6=-2,1.5,IF(N18-N6=-1,0.8,IF(N18-N6=0,0.4,IF(N18-N6=1,0,IF(N18-N6<=2>15,0,_xludf.IF))))))) -> 0.4 | O19: =IF(O18=0,0,IF(O18-O6=-3,3,IF(O18-O6=-2,1.5,IF(O18-O6=-1,0.8,IF(O18-O6=0,0.4,IF(O18-O6=1,0,IF(O18-O6<=2>15,0,_xludf.IF))))))) -> 0.4 | P19: =IF(P18=0,0,IF(P18-P6=-3,3,IF(P18-P6=-2,1.5,IF(P18-P6=-1,0.8,IF(P18-P6=0,0.4,IF(P18-P6=1,0,IF(P18-P6<=2>15,0,_xludf.IF))))))) -> 0 | Q19: =IF(Q18=0,0,IF(Q18-Q6=-3,3,IF(Q18-Q6=-2,1.5,IF(Q18-Q6=-1,0.8,IF(Q18-Q6=0,0.4,IF(Q18-Q6=1,0,IF(Q18-Q6<=2>15,0,_xludf.IF))))))) -> 0 | R19: =IF(R18=0,0,IF(R18-R6=-3,3,IF(R18-R6=-2,1.5,IF(R18-R6=-1,0.8,IF(R18-R6=0,0.4,IF(R18-R6=1,0,IF(R18-R6<=2>15,0,_xludf.IF))))))) -> 0 | S19: =IF(S18=0,0,IF(S18-S6=-3,3,IF(S18-S6=-2,1.5,IF(S18-S6=-1,0.8,IF(S18-S6=0,0.4,IF(S18-S6=1,0,IF(S18-S6<=2>15,0,_xludf.IF))))))) -> 0 | T19: =IF(T18=0,0,IF(T18-T6=-3,3,IF(T18-T6=-2,1.5,IF(T18-T6=-1,0.8,IF(T18-T6=0,0.4,IF(T18-T6=1,0,IF(T18-T6<=2>15,0,_xludf.IF))))))) -> 0 | U19: =IF(U18=0,0,IF(U18-U6=-3,3,IF(U18-U6=-2,1.5,IF(U18-U6=-1,0.8,IF(U18-U6=0,0.4,IF(U18-U6=1,0,IF(U18-U6<=2>15,0,_xludf.IF))))))) -> 0.4 | V19: =IF(V18=0,0,IF(V18-V6=-3,3,IF(V18-V6=-2,1.5,IF(V18-V6=-1,0.8,IF(V18-V6=0,0.4,IF(V18-V6=1,0,IF(V18-V6<=2>15,0,_xludf.IF))))))) -> 0 | W19: =SUM(N19:V19) -> 1.2 | X19: =L19+W19 -> 4.4
A20: Tommy | B20: Gross Score | C20: 7 | D20: 5 | E20: 5 | F20: 4 | G20: 6 | H20: 7 | I20: 3 | J20: 7 | K20: 4 | L20: =SUM(C20:K20) -> 48 | M20: Gross Score | N20: 4 | O20: 5 | P20: 5 | Q20: 5 | R20: 5 | S20: 4 | T20: 7 | U20: 4 | V20: 6 | W20: =SUM(N20:V20) -> 45 | X20: =L20+W20 -> 93
A21: 14 | B21: Handicap | C21: -1 | D21: -1 | F21: -1 | G21: -1 | H21: -1 | J21: -1 | K21: -1 | L21: =SUM(C21:K21) -> -7 | M21: Handicap | N21: -1 | O21: -1 | Q21: -1 | R21: -1 | S21: -1 | T21: -1 | V21: -1 | W21: =SUM(N21:V21) -> -7 | X21: =L21+W21 -> -14
B22: Net Score | C22: =SUM(C20:C21) -> 6 | D22: =SUM(D20:D21) -> 4 | E22: =SUM(E20:E21) -> 5 | F22: =SUM(F20:F21) -> 3 | G22: =SUM(G20:G21) -> 5 | H22: =SUM(H20:H21) -> 6 | I22: =SUM(I20:I21) -> 3 | J22: =SUM(J20:J21) -> 6 | K22: =SUM(K20:K21) -> 3 | L22: =SUM(C22:K22) -> 41 | M22: Net Score | N22: =SUM(N20:N21) -> 3 | O22: =SUM(O20:O21) -> 4 | P22: =SUM(P20:P21) -> 5 | Q22: =SUM(Q20:Q21) -> 4 | R22: =SUM(R20:R21) -> 4 | S22: =SUM(S20:S21) -> 3 | T22: =SUM(T20:T21) -> 6 | U22: =SUM(U20:U21) -> 4 | V22: =SUM(V20:V21) -> 5 | W22: =SUM(N22:V22) -> 38 | X22: =L22+W22 -> 79
B23: Points | C23: =IF(C22=0,0,IF(C22-C6=-3,3,IF(C22-C6=-2,1.5,IF(C22-C6=-1,0.8,IF(C22-C6=0,0.4,IF(C22-C6=1,0,IF(C22-C6<=2>15,0,_xludf.IF))))))) -> 0 | D23: =IF(D22=0,0,IF(D22-D6=-3,3,IF(D22-D6=-2,1.5,IF(D22-D6=-1,0.8,IF(D22-D6=0,0.4,IF(D22-D6=1,0,IF(D22-D6<=2>15,0,_xludf.IF))))))) -> 0.4 | E23: =IF(E22=0,0,IF(E22-E6=-3,3,IF(E22-E6=-2,1.5,IF(E22-E6=-1,0.8,IF(E22-E6=0,0.4,IF(E22-E6=1,0,IF(E22-E6<=2>15,0,_xludf.IF))))))) -> 0 | F23: =IF(F22=0,0,IF(F22-F6=-3,3,IF(F22-F6=-2,1.5,IF(F22-F6=-1,0.8,IF(F22-F6=0,0.4,IF(F22-F6=1,0,IF(F22-F6<=2>15,0,_xludf.IF))))))) -> 0.8 | G23: =IF(G22=0,0,IF(G22-G6=-3,3,IF(G22-G6=-2,1.5,IF(G22-G6=-1,0.8,IF(G22-G6=0,0.4,IF(G22-G6=1,0,IF(G22-G6<=2>15,0,_xludf.IF))))))) -> 0 | H23: =IF(H22=0,0,IF(H22-H6=-3,3,IF(H22-H6=-2,1.5,IF(H22-H6=-1,0.8,IF(H22-H6=0,0.4,IF(H22-H6=1,0,IF(H22-H6<=2>15,0,_xludf.IF))))))) -> 0 | I23: =IF(I22=0,0,IF(I22-I6=-3,3,IF(I22-I6=-2,1.5,IF(I22-I6=-1,0.8,IF(I22-I6=0,0.4,IF(I22-I6=1,0,IF(I22-I6<=2>15,0,_xludf.IF))))))) -> 0.4 | J23: =IF(J22=0,0,IF(J22-J6=-3,3,IF(J22-J6=-2,1.5,IF(J22-J6=-1,0.8,IF(J22-J6=0,0.4,IF(J22-J6=1,0,IF(J22-J6<=2>15,0,_xludf.IF))))))) -> 0 | K23: =IF(K22=0,0,IF(K22-K6=-3,3,IF(K22-K6=-2,1.5,IF(K22-K6=-1,0.8,IF(K22-K6=0,0.4,IF(K22-K6=1,0,IF(K22-K6<=2>15,0,_xludf.IF))))))) -> 0.8 | L23: =SUM(C23:K23) -> 2.4 | M23: Points | N23: =IF(N22=0,0,IF(N22-N6=-3,3,IF(N22-N6=-2,1.5,IF(N22-N6=-1,0.8,IF(N22-N6=0,0.4,IF(N22-N6=1,0,IF(N22-N6<=2>15,0,_xludf.IF))))))) -> 0.8 | O23: =IF(O22=0,0,IF(O22-O6=-3,3,IF(O22-O6=-2,1.5,IF(O22-O6=-1,0.8,IF(O22-O6=0,0.4,IF(O22-O6=1,0,IF(O22-O6<=2>15,0,_xludf.IF))))))) -> 0.4 | P23: =IF(P22=0,0,IF(P22-P6=-3,3,IF(P22-P6=-2,1.5,IF(P22-P6=-1,0.8,IF(P22-P6=0,0.4,IF(P22-P6=1,0,IF(P22-P6<=2>15,0,_xludf.IF))))))) -> 0 | Q23: =IF(Q22=0,0,IF(Q22-Q6=-3,3,IF(Q22-Q6=-2,1.5,IF(Q22-Q6=-1,0.8,IF(Q22-Q6=0,0.4,IF(Q22-Q6=1,0,IF(Q22-Q6<=2>15,0,_xludf.IF))))))) -> 0.4 | R23: =IF(R22=0,0,IF(R22-R6=-3,3,IF(R22-R6=-2,1.5,IF(R22-R6=-1,0.8,IF(R22-R6=0,0.4,IF(R22-R6=1,0,IF(R22-R6<=2>15,0,_xludf.IF))))))) -> 0.8 | S23: =IF(S22=0,0,IF(S22-S6=-3,3,IF(S22-S6=-2,1.5,IF(S22-S6=-1,0.8,IF(S22-S6=0,0.4,IF(S22-S6=1,0,IF(S22-S6<=2>15,0,_xludf.IF))))))) -> 0.8 | T23: =IF(T22=0,0,IF(T22-T6=-3,3,IF(T22-T6=-2,1.5,IF(T22-T6=-1,0.8,IF(T22-T6=0,0.4,IF(T22-T6=1,0,IF(T22-T6<=2>15,0,_xludf.IF))))))) -> 0 | U23: =IF(U22=0,0,IF(U22-U6=-3,3,IF(U22-U6=-2,1.5,IF(U22-U6=-1,0.8,IF(U22-U6=0,0.4,IF(U22-U6=1,0,IF(U22-U6<=2>15,0,_xludf.IF))))))) -> 0 | V23: =IF(V22=0,0,IF(V22-V6=-3,3,IF(V22-V6=-2,1.5,IF(V22-V6=-1,0.8,IF(V22-V6=0,0.4,IF(V22-V6=1,0,IF(V22-V6<=2>15,0,_xludf.IF))))))) -> 0.4 | W23: =SUM(N23:V23) -> 3.6 | X23: =L23+W23 -> 6
A24: Oaks | B24: Gross Score | C24: 7 | D24: 5 | E24: 3 | F24: 5 | G24: 5 | H24: 6 | I24: 4 | J24: 5 | K24: 8 | L24: =SUM(C24:K24) -> 48 | M24: Gross Score | N24: 4 | O24: 7 | P24: 4 | Q24: 5 | R24: 6 | S24: 5 | T24: 5 | U24: 4 | V24: 6 | W24: =SUM(N24:V24) -> 46 | X24: =L24+W24 -> 94
A25: 4 | B25: Handicap | H25: -1 | J25: -1 | L25: =SUM(C25:K25) -> -2 | M25: Handicap | T25: -1 | V25: -1 | W25: =SUM(N25:V25) -> -2 | X25: =L25+W25 -> -4
B26: Net Score | C26: =SUM(C24:C25) -> 7 | D26: =SUM(D24:D25) -> 5 | E26: =SUM(E24:E25) -> 3 | F26: =SUM(F24:F25) -> 5 | G26: =SUM(G24:G25) -> 5 | H26: =SUM(H24:H25) -> 5 | I26: =SUM(I24:I25) -> 4 | J26: =SUM(J24:J25) -> 4 | K26: =SUM(K24:K25) -> 8 | L26: =SUM(C26:K26) -> 46 | M26: Net Score | N26: =SUM(N24:N25) -> 4 | O26: =SUM(O24:O25) -> 7 | P26: =SUM(P24:P25) -> 4 | Q26: =SUM(Q24:Q25) -> 5 | R26: =SUM(R24:R25) -> 6 | S26: =SUM(S24:S25) -> 5 | T26: =SUM(T24:T25) -> 4 | U26: =SUM(U24:U25) -> 4 | V26: =SUM(V24:V25) -> 5 | W26: =SUM(N26:V26) -> 44 | X26: =L26+W26 -> 90
B27: Points | C27: =IF(C26=0,0,IF(C26-C6=-3,3,IF(C26-C6=-2,1.5,IF(C26-C6=-1,0.8,IF(C26-C6=0,0.4,IF(C26-C6=1,0,IF(C26-C6<=2>15,0,_xludf.IF))))))) -> 0 | D27: =IF(D26=0,0,IF(D26-D6=-3,3,IF(D26-D6=-2,1.5,IF(D26-D6=-1,0.8,IF(D26-D6=0,0.4,IF(D26-D6=1,0,IF(D26-D6<=2>15,0,_xludf.IF))))))) -> 0 | E27: =IF(E26=0,0,IF(E26-E6=-3,3,IF(E26-E6=-2,1.5,IF(E26-E6=-1,0.8,IF(E26-E6=0,0.4,IF(E26-E6=1,0,IF(E26-E6<=2>15,0,_xludf.IF))))))) -> 0.4 | F27: =IF(F26=0,0,IF(F26-F6=-3,3,IF(F26-F6=-2,1.5,IF(F26-F6=-1,0.8,IF(F26-F6=0,0.4,IF(F26-F6=1,0,IF(F26-F6<=2>15,0,_xludf.IF))))))) -> 0 | G27: =IF(G26=0,0,IF(G26-G6=-3,3,IF(G26-G6=-2,1.5,IF(G26-G6=-1,0.8,IF(G26-G6=0,0.4,IF(G26-G6=1,0,IF(G26-G6<=2>15,0,_xludf.IF))))))) -> 0 | H27: =IF(H26=0,0,IF(H26-H6=-3,3,IF(H26-H6=-2,1.5,IF(H26-H6=-1,0.8,IF(H26-H6=0,0.4,IF(H26-H6=1,0,IF(H26-H6<=2>15,0,_xludf.IF))))))) -> 0 | I27: =IF(I26=0,0,IF(I26-I6=-3,3,IF(I26-I6=-2,1.5,IF(I26-I6=-1,0.8,IF(I26-I6=0,0.4,IF(I26-I6=1,0,IF(I26-I6<=2>15,0,_xludf.IF))))))) -> 0 | J27: =IF(J26=0,0,IF(J26-J6=-3,3,IF(J26-J6=-2,1.5,IF(J26-J6=-1,0.8,IF(J26-J6=0,0.4,IF(J26-J6=1,0,IF(J26-J6<=2>15,0,_xludf.IF))))))) -> 0.8 | K27: =IF(K26=0,0,IF(K26-K6=-3,3,IF(K26-K6=-2,1.5,IF(K26-K6=-1,0.8,IF(K26-K6=0,0.4,IF(K26-K6=1,0,IF(K26-K6<=2>15,0,_xludf.IF))))))) -> 0 | L27: =SUM(C27:K27) -> 1.2 | M27: Points | N27: =IF(N26=0,0,IF(N26-N6=-3,3,IF(N26-N6=-2,1.5,IF(N26-N6=-1,0.8,IF(N26-N6=0,0.4,IF(N26-N6=1,0,IF(N26-N6<=2>15,0,_xludf.IF))))))) -> 0.4 | O27: =IF(O26=0,0,IF(O26-O6=-3,3,IF(O26-O6=-2,1.5,IF(O26-O6=-1,0.8,IF(O26-O6=0,0.4,IF(O26-O6=1,0,IF(O26-O6<=2>15,0,_xludf.IF))))))) -> 0 | P27: =IF(P26=0,0,IF(P26-P6=-3,3,IF(P26-P6=-2,1.5,IF(P26-P6=-1,0.8,IF(P26-P6=0,0.4,IF(P26-P6=1,0,IF(P26-P6<=2>15,0,_xludf.IF))))))) -> 0 | Q27: =IF(Q26=0,0,IF(Q26-Q6=-3,3,IF(Q26-Q6=-2,1.5,IF(Q26-Q6=-1,0.8,IF(Q26-Q6=0,0.4,IF(Q26-Q6=1,0,IF(Q26-Q6<=2>15,0,_xludf.IF))))))) -> 0 | R27: =IF(R26=0,0,IF(R26-R6=-3,3,IF(R26-R6=-2,1.5,IF(R26-R6=-1,0.8,IF(R26-R6=0,0.4,IF(R26-R6=1,0,IF(R26-R6<=2>15,0,_xludf.IF))))))) -> 0 | S27: =IF(S26=0,0,IF(S26-S6=-3,3,IF(S26-S6=-2,1.5,IF(S26-S6=-1,0.8,IF(S26-S6=0,0.4,IF(S26-S6=1,0,IF(S26-S6<=2>15,0,_xludf.IF))))))) -> 0 | T27: =IF(T26=0,0,IF(T26-T6=-3,3,IF(T26-T6=-2,1.5,IF(T26-T6=-1,0.8,IF(T26-T6=0,0.4,IF(T26-T6=1,0,IF(T26-T6<=2>15,0,_xludf.IF))))))) -> 0.4 | U27: =IF(U26=0,0,IF(U26-U6=-3,3,IF(U26-U6=-2,1.5,IF(U26-U6=-1,0.8,IF(U26-U6=0,0.4,IF(U26-U6=1,0,IF(U26-U6<=2>15,0,_xludf.IF))))))) -> 0 | V27: =IF(V26=0,0,IF(V26-V6=-3,3,IF(V26-V6=-2,1.5,IF(V26-V6=-1,0.8,IF(V26-V6=0,0.4,IF(V26-V6=1,0,IF(V26-V6<=2>15,0,_xludf.IF))))))) -> 0.4 | W27: =SUM(N27:V27) -> 1.2 | X27: =L27+W27 -> 2.4
A28: Frazier | B28: Gross Score | C28: 5 | D28: 5 | E28: 4 | F28: 5 | G28: 4 | H28: 4 | I28: 5 | J28: 4 | K28: 6 | L28: =SUM(C28:K28) -> 42 | M28: Gross Score | N28: 5 | O28: 8 | P28: 2 | Q28: 5 | R28: 5 | S28: 5 | T28: 5 | U28: 3 | V28: 6 | W28: =SUM(N28:V28) -> 44 | X28: =L28+W28 -> 86
A29: 6 | B29: Handicap | C29: -1 | H29: -1 | J29: -1 | L29: =SUM(C29:K29) -> -3 | M29: Handicap | O29: -1 | T29: -1 | V29: -1 | W29: =SUM(N29:V29) -> -3 | X29: =L29+W29 -> -6
B30: Net Score | C30: =SUM(C28:C29) -> 4 | D30: =SUM(D28:D29) -> 5 | E30: =SUM(E28:E29) -> 4 | F30: =SUM(F28:F29) -> 5 | G30: =SUM(G28:G29) -> 4 | H30: =SUM(H28:H29) -> 3 | I30: =SUM(I28:I29) -> 5 | J30: =SUM(J28:J29) -> 3 | K30: =SUM(K28:K29) -> 6 | L30: =SUM(C30:K30) -> 39 | M30: Net Score | N30: =SUM(N28:N29) -> 5 | O30: =SUM(O28:O29) -> 7 | P30: =SUM(P28:P29) -> 2 | Q30: =SUM(Q28:Q29) -> 5 | R30: =SUM(R28:R29) -> 5 | S30: =SUM(S28:S29) -> 5 | T30: =SUM(T28:T29) -> 4 | U30: =SUM(U28:U29) -> 3 | V30: =SUM(V28:V29) -> 5 | W30: =SUM(N30:V30) -> 41 | X30: =L30+W30 -> 80
B31: Points | C31: =IF(C30=0,0,IF(C30-C6=-3,3,IF(C30-C6=-2,1.5,IF(C30-C6=-1,0.8,IF(C30-C6=0,0.4,IF(C30-C6=1,0,IF(C30-C6<=2>15,0,_xludf.IF))))))) -> 0.4 | D31: =IF(D30=0,0,IF(D30-D6=-3,3,IF(D30-D6=-2,1.5,IF(D30-D6=-1,0.8,IF(D30-D6=0,0.4,IF(D30-D6=1,0,IF(D30-D6<=2>15,0,_xludf.IF))))))) -> 0 | E31: =IF(E30=0,0,IF(E30-E6=-3,3,IF(E30-E6=-2,1.5,IF(E30-E6=-1,0.8,IF(E30-E6=0,0.4,IF(E30-E6=1,0,IF(E30-E6<=2>15,0,_xludf.IF))))))) -> 0 | F31: =IF(F30=0,0,IF(F30-F6=-3,3,IF(F30-F6=-2,1.5,IF(F30-F6=-1,0.8,IF(F30-F6=0,0.4,IF(F30-F6=1,0,IF(F30-F6<=2>15,0,_xludf.IF))))))) -> 0 | G31: =IF(G30=0,0,IF(G30-G6=-3,3,IF(G30-G6=-2,1.5,IF(G30-G6=-1,0.8,IF(G30-G6=0,0.4,IF(G30-G6=1,0,IF(G30-G6<=2>15,0,_xludf.IF))))))) -> 0.4 | H31: =IF(H30=0,0,IF(H30-H6=-3,3,IF(H30-H6=-2,1.5,IF(H30-H6=-1,0.8,IF(H30-H6=0,0.4,IF(H30-H6=1,0,IF(H30-H6<=2>15,0,_xludf.IF))))))) -> 0.8 | I31: =IF(I30=0,0,IF(I30-I6=-3,3,IF(I30-I6=-2,1.5,IF(I30-I6=-1,0.8,IF(I30-I6=0,0.4,IF(I30-I6=1,0,IF(I30-I6<=2>15,0,_xludf.IF))))))) -> 0 | J31: =IF(J30=0,0,IF(J30-J6=-3,3,IF(J30-J6=-2,1.5,IF(J30-J6=-1,0.8,IF(J30-J6=0,0.4,IF(J30-J6=1,0,IF(J30-J6<=2>15,0,_xludf.IF))))))) -> 1.5 | K31: =IF(K30=0,0,IF(K30-K6=-3,3,IF(K30-K6=-2,1.5,IF(K30-K6=-1,0.8,IF(K30-K6=0,0.4,IF(K30-K6=1,0,IF(K30-K6<=2>15,0,_xludf.IF))))))) -> 0 | L31: =SUM(C31:K31) -> 3.1 | M31: Points | N31: =IF(N30=0,0,IF(N30-N6=-3,3,IF(N30-N6=-2,1.5,IF(N30-N6=-1,0.8,IF(N30-N6=0,0.4,IF(N30-N6=1,0,IF(N30-N6<=2>15,0,_xludf.IF))))))) -> 0 | O31: =IF(O30=0,0,IF(O30-O6=-3,3,IF(O30-O6=-2,1.5,IF(O30-O6=-1,0.8,IF(O30-O6=0,0.4,IF(O30-O6=1,0,IF(O30-O6<=2>15,0,_xludf.IF))))))) -> 0 | P31: =IF(P30=0,0,IF(P30-P6=-3,3,IF(P30-P6=-2,1.5,IF(P30-P6=-1,0.8,IF(P30-P6=0,0.4,IF(P30-P6=1,0,IF(P30-P6<=2>15,0,_xludf.IF))))))) -> 0.8 | Q31: =IF(Q30=0,0,IF(Q30-Q6=-3,3,IF(Q30-Q6=-2,1.5,IF(Q30-Q6=-1,0.8,IF(Q30-Q6=0,0.4,IF(Q30-Q6=1,0,IF(Q30-Q6<=2>15,0,_xludf.IF))))))) -> 0 | R31: =IF(R30=0,0,IF(R30-R6=-3,3,IF(R30-R6=-2,1.5,IF(R30-R6=-1,0.8,IF(R30-R6=0,0.4,IF(R30-R6=1,0,IF(R30-R6<=2>15,0,_xludf.IF))))))) -> 0.4 | S31: =IF(S30=0,0,IF(S30-S6=-3,3,IF(S30-S6=-2,1.5,IF(S30-S6=-1,0.8,IF(S30-S6=0,0.4,IF(S30-S6=1,0,IF(S30-S6<=2>15,0,_xludf.IF))))))) -> 0 | T31: =IF(T30=0,0,IF(T30-T6=-3,3,IF(T30-T6=-2,1.5,IF(T30-T6=-1,0.8,IF(T30-T6=0,0.4,IF(T30-T6=1,0,IF(T30-T6<=2>15,0,_xludf.IF))))))) -> 0.4 | U31: =IF(U30=0,0,IF(U30-U6=-3,3,IF(U30-U6=-2,1.5,IF(U30-U6=-1,0.8,IF(U30-U6=0,0.4,IF(U30-U6=1,0,IF(U30-U6<=2>15,0,_xludf.IF))))))) -> 0.4 | V31: =IF(V30=0,0,IF(V30-V6=-3,3,IF(V30-V6=-2,1.5,IF(V30-V6=-1,0.8,IF(V30-V6=0,0.4,IF(V30-V6=1,0,IF(V30-V6<=2>15,0,_xludf.IF))))))) -> 0.4 | W31: =SUM(N31:V31) -> 2.4 | X31: =L31+W31 -> 5.5
A32: Vince | B32: Gross Score | C32: 7 | D32: 6 | E32: 3 | F32: 5 | G32: 4 | H32: 5 | I32: 2 | J32: 6 | K32: 4 | L32: =SUM(C32:K32) -> 42 | M32: Gross Score | N32: 5 | O32: 3 | P32: 4 | Q32: 4 | R32: 7 | S32: 4 | T32: 7 | U32: 4 | V32: 5 | W32: =SUM(N32:V32) -> 43 | X32: =L32+W32 -> 85
A33: 8 | B33: Handicap | C33: -1 | G33: -1 | H33: -1 | J33: -1 | L33: =SUM(C33:K33) -> -4 | M33: Handicap | O33: -1 | Q33: -1 | T33: -1 | V33: -1 | W33: =SUM(N33:V33) -> -4 | X33: =L33+W33 -> -8
B34: Net Score | C34: =SUM(C32:C33) -> 6 | D34: =SUM(D32:D33) -> 6 | E34: =SUM(E32:E33) -> 3 | F34: =SUM(F32:F33) -> 5 | G34: =SUM(G32:G33) -> 3 | H34: =SUM(H32:H33) -> 4 | I34: =SUM(I32:I33) -> 2 | J34: =SUM(J32:J33) -> 5 | K34: =SUM(K32:K33) -> 4 | L34: =SUM(C34:K34) -> 38 | M34: Net Score | N34: =SUM(N32:N33) -> 5 | O34: =SUM(O32:O33) -> 2 | P34: =SUM(P32:P33) -> 4 | Q34: =SUM(Q32:Q33) -> 3 | R34: =SUM(R32:R33) -> 7 | S34: =SUM(S32:S33) -> 4 | T34: =SUM(T32:T33) -> 6 | U34: =SUM(U32:U33) -> 4 | V34: =SUM(V32:V33) -> 4 | W34: =SUM(N34:V34) -> 39 | X34: =L34+W34 -> 77
B35: Points | C35: =IF(C34=0,0,IF(C34-C6=-3,3,IF(C34-C6=-2,1.5,IF(C34-C6=-1,0.8,IF(C34-C6=0,0.4,IF(C34-C6=1,0,IF(C34-C6<=2>15,0,_xludf.IF))))))) -> 0 | D35: =IF(D34=0,0,IF(D34-D6=-3,3,IF(D34-D6=-2,1.5,IF(D34-D6=-1,0.8,IF(D34-D6=0,0.4,IF(D34-D6=1,0,IF(D34-D6<=2>15,0,_xludf.IF))))))) -> 0 | E35: =IF(E34=0,0,IF(E34-E6=-3,3,IF(E34-E6=-2,1.5,IF(E34-E6=-1,0.8,IF(E34-E6=0,0.4,IF(E34-E6=1,0,IF(E34-E6<=2>15,0,_xludf.IF))))))) -> 0.4 | F35: =IF(F34=0,0,IF(F34-F6=-3,3,IF(F34-F6=-2,1.5,IF(F34-F6=-1,0.8,IF(F34-F6=0,0.4,IF(F34-F6=1,0,IF(F34-F6<=2>15,0,_xludf.IF))))))) -> 0 | G35: =IF(G34=0,0,IF(G34-G6=-3,3,IF(G34-G6=-2,1.5,IF(G34-G6=-1,0.8,IF(G34-G6=0,0.4,IF(G34-G6=1,0,IF(G34-G6<=2>15,0,_xludf.IF))))))) -> 0.8 | H35: =IF(H34=0,0,IF(H34-H6=-3,3,IF(H34-H6=-2,1.5,IF(H34-H6=-1,0.8,IF(H34-H6=0,0.4,IF(H34-H6=1,0,IF(H34-H6<=2>15,0,_xludf.IF))))))) -> 0.4 | I35: =IF(I34=0,0,IF(I34-I6=-3,3,IF(I34-I6=-2,1.5,IF(I34-I6=-1,0.8,IF(I34-I6=0,0.4,IF(I34-I6=1,0,IF(I34-I6<=2>15,0,_xludf.IF))))))) -> 0.8 | J35: =IF(J34=0,0,IF(J34-J6=-3,3,IF(J34-J6=-2,1.5,IF(J34-J6=-1,0.8,IF(J34-J6=0,0.4,IF(J34-J6=1,0,IF(J34-J6<=2>15,0,_xludf.IF))))))) -> 0.4 | K35: =IF(K34=0,0,IF(K34-K6=-3,3,IF(K34-K6=-2,1.5,IF(K34-K6=-1,0.8,IF(K34-K6=0,0.4,IF(K34-K6=1,0,IF(K34-K6<=2>15,0,_xludf.IF))))))) -> 0.4 | L35: =SUM(C35:K35) -> 3.2 | M35: Points | N35: =IF(N34=0,0,IF(N34-N6=-3,3,IF(N34-N6=-2,1.5,IF(N34-N6=-1,0.8,IF(N34-N6=0,0.4,IF(N34-N6=1,0,IF(N34-N6<=2>15,0,_xludf.IF))))))) -> 0 | O35: =IF(O34=0,0,IF(O34-O6=-3,3,IF(O34-O6=-2,1.5,IF(O34-O6=-1,0.8,IF(O34-O6=0,0.4,IF(O34-O6=1,0,IF(O34-O6<=2>15,0,_xludf.IF))))))) -> 1.5 | P35: =IF(P34=0,0,IF(P34-P6=-3,3,IF(P34-P6=-2,1.5,IF(P34-P6=-1,0.8,IF(P34-P6=0,0.4,IF(P34-P6=1,0,IF(P34-P6<=2>15,0,_xludf.IF))))))) -> 0 | Q35: =IF(Q34=0,0,IF(Q34-Q6=-3,3,IF(Q34-Q6=-2,1.5,IF(Q34-Q6=-1,0.8,IF(Q34-Q6=0,0.4,IF(Q34-Q6=1,0,IF(Q34-Q6<=2>15,0,_xludf.IF))))))) -> 0.8 | R35: =IF(R34=0,0,IF(R34-R6=-3,3,IF(R34-R6=-2,1.5,IF(R34-R6=-1,0.8,IF(R34-R6=0,0.4,IF(R34-R6=1,0,IF(R34-R6<=2>15,0,_xludf.IF))))))) -> 0 | S35: =IF(S34=0,0,IF(S34-S6=-3,3,IF(S34-S6=-2,1.5,IF(S34-S6=-1,0.8,IF(S34-S6=0,0.4,IF(S34-S6=1,0,IF(S34-S6<=2>15,0,_xludf.IF))))))) -> 0.4 | T35: =IF(T34=0,0,IF(T34-T6=-3,3,IF(T34-T6=-2,1.5,IF(T34-T6=-1,0.8,IF(T34-T6=0,0.4,IF(T34-T6=1,0,IF(T34-T6<=2>15,0,_xludf.IF))))))) -> 0 | U35: =IF(U34=0,0,IF(U34-U6=-3,3,IF(U34-U6=-2,1.5,IF(U34-U6=-1,0.8,IF(U34-U6=0,0.4,IF(U34-U6=1,0,IF(U34-U6<=2>15,0,_xludf.IF))))))) -> 0 | V35: =IF(V34=0,0,IF(V34-V6=-3,3,IF(V34-V6=-2,1.5,IF(V34-V6=-1,0.8,IF(V34-V6=0,0.4,IF(V34-V6=1,0,IF(V34-V6<=2>15,0,_xludf.IF))))))) -> 0.8 | W35: =SUM(N35:V35) -> 3.5 | X35: =L35+W35 -> 6.7
A36: Uncle Mike | B36: Gross Score | C36: 6 | D36: 7 | E36: 4 | F36: 10 | G36: 6 | H36: 6 | I36: 3 | J36: 6 | K36: 5 | L36: =SUM(C36:K36) -> 53 | M36: Gross Score | N36: 6 | O36: 6 | P36: 7 | Q36: 7 | R36: 8 | S36: 6 | T36: 8 | U36: 4 | V36: 6 | W36: =SUM(N36:V36) -> 58 | X36: =L36+W36 -> 111
A37: 17 | B37: Handicap | C37: -1 | D37: -1 | F37: -1 | G37: -1 | H37: -1 | I37: -1 | J37: -1 | K37: -1 | L37: =SUM(C37:K37) -> -8 | M37: Handicap | N37: -1 | O37: -1 | P37: -1 | Q37: -1 | R37: -1 | S37: -1 | T37: -1 | U37: -1 | V37: -1 | W37: =SUM(N37:V37) -> -9 | X37: =L37+W37 -> -17
B38: Net Score | C38: =SUM(C36:C37) -> 5 | D38: =SUM(D36:D37) -> 6 | E38: =SUM(E36:E37) -> 4 | F38: =SUM(F36:F37) -> 9 | G38: =SUM(G36:G37) -> 5 | H38: =SUM(H36:H37) -> 5 | I38: =SUM(I36:I37) -> 2 | J38: =SUM(J36:J37) -> 5 | K38: =SUM(K36:K37) -> 4 | L38: =SUM(C38:K38) -> 45 | M38: Net Score | N38: =SUM(N36:N37) -> 5 | O38: =SUM(O36:O37) -> 5 | P38: =SUM(P36:P37) -> 6 | Q38: =SUM(Q36:Q37) -> 6 | R38: =SUM(R36:R37) -> 7 | S38: =SUM(S36:S37) -> 5 | T38: =SUM(T36:T37) -> 7 | U38: =SUM(U36:U37) -> 3 | V38: =SUM(V36:V37) -> 5 | W38: =SUM(N38:V38) -> 49 | X38: =L38+W38 -> 94
B39: Points | C39: =IF(C38=0,0,IF(C38-C6=-3,3,IF(C38-C6=-2,1.5,IF(C38-C6=-1,0.8,IF(C38-C6=0,0.4,IF(C38-C6=1,0,IF(C38-C6<=2>15,0,_xludf.IF))))))) -> 0 | D39: =IF(D38=0,0,IF(D38-D6=-3,3,IF(D38-D6=-2,1.5,IF(D38-D6=-1,0.8,IF(D38-D6=0,0.4,IF(D38-D6=1,0,IF(D38-D6<=2>15,0,_xludf.IF))))))) -> 0 | E39: =IF(E38=0,0,IF(E38-E6=-3,3,IF(E38-E6=-2,1.5,IF(E38-E6=-1,0.8,IF(E38-E6=0,0.4,IF(E38-E6=1,0,IF(E38-E6<=2>15,0,_xludf.IF))))))) -> 0 | F39: =IF(F38=0,0,IF(F38-F6=-3,3,IF(F38-F6=-2,1.5,IF(F38-F6=-1,0.8,IF(F38-F6=0,0.4,IF(F38-F6=1,0,IF(F38-F6<=2>15,0,_xludf.IF))))))) -> 0 | G39: =IF(G38=0,0,IF(G38-G6=-3,3,IF(G38-G6=-2,1.5,IF(G38-G6=-1,0.8,IF(G38-G6=0,0.4,IF(G38-G6=1,0,IF(G38-G6<=2>15,0,_xludf.IF))))))) -> 0 | H39: =IF(H38=0,0,IF(H38-H6=-3,3,IF(H38-H6=-2,1.5,IF(H38-H6=-1,0.8,IF(H38-H6=0,0.4,IF(H38-H6=1,0,IF(H38-H6<=2>15,0,_xludf.IF))))))) -> 0 | I39: =IF(I38=0,0,IF(I38-I6=-3,3,IF(I38-I6=-2,1.5,IF(I38-I6=-1,0.8,IF(I38-I6=0,0.4,IF(I38-I6=1,0,IF(I38-I6<=2>15,0,_xludf.IF))))))) -> 0.8 | J39: =IF(J38=0,0,IF(J38-J6=-3,3,IF(J38-J6=-2,1.5,IF(J38-J6=-1,0.8,IF(J38-J6=0,0.4,IF(J38-J6=1,0,IF(J38-J6<=2>15,0,_xludf.IF))))))) -> 0.4 | K39: =IF(K38=0,0,IF(K38-K6=-3,3,IF(K38-K6=-2,1.5,IF(K38-K6=-1,0.8,IF(K38-K6=0,0.4,IF(K38-K6=1,0,IF(K38-K6<=2>15,0,_xludf.IF))))))) -> 0.4 | L39: =SUM(C39:K39) -> 1.6 | M39: Points | N39: =IF(N38=0,0,IF(N38-N6=-3,3,IF(N38-N6=-2,1.5,IF(N38-N6=-1,0.8,IF(N38-N6=0,0.4,IF(N38-N6=1,0,IF(N38-N6<=2>15,0,_xludf.IF))))))) -> 0 | O39: =IF(O38=0,0,IF(O38-O6=-3,3,IF(O38-O6=-2,1.5,IF(O38-O6=-1,0.8,IF(O38-O6=0,0.4,IF(O38-O6=1,0,IF(O38-O6<=2>15,0,_xludf.IF))))))) -> 0 | P39: =IF(P38=0,0,IF(P38-P6=-3,3,IF(P38-P6=-2,1.5,IF(P38-P6=-1,0.8,IF(P38-P6=0,0.4,IF(P38-P6=1,0,IF(P38-P6<=2>15,0,_xludf.IF))))))) -> 0 | Q39: =IF(Q38=0,0,IF(Q38-Q6=-3,3,IF(Q38-Q6=-2,1.5,IF(Q38-Q6=-1,0.8,IF(Q38-Q6=0,0.4,IF(Q38-Q6=1,0,IF(Q38-Q6<=2>15,0,_xludf.IF))))))) -> 0 | R39: =IF(R38=0,0,IF(R38-R6=-3,3,IF(R38-R6=-2,1.5,IF(R38-R6=-1,0.8,IF(R38-R6=0,0.4,IF(R38-R6=1,0,IF(R38-R6<=2>15,0,_xludf.IF))))))) -> 0 | S39: =IF(S38=0,0,IF(S38-S6=-3,3,IF(S38-S6=-2,1.5,IF(S38-S6=-1,0.8,IF(S38-S6=0,0.4,IF(S38-S6=1,0,IF(S38-S6<=2>15,0,_xludf.IF))))))) -> 0 | T39: =IF(T38=0,0,IF(T38-T6=-3,3,IF(T38-T6=-2,1.5,IF(T38-T6=-1,0.8,IF(T38-T6=0,0.4,IF(T38-T6=1,0,IF(T38-T6<=2>15,0,_xludf.IF))))))) -> 0 | U39: =IF(U38=0,0,IF(U38-U6=-3,3,IF(U38-U6=-2,1.5,IF(U38-U6=-1,0.8,IF(U38-U6=0,0.4,IF(U38-U6=1,0,IF(U38-U6<=2>15,0,_xludf.IF))))))) -> 0.4 | V39: =IF(V38=0,0,IF(V38-V6=-3,3,IF(V38-V6=-2,1.5,IF(V38-V6=-1,0.8,IF(V38-V6=0,0.4,IF(V38-V6=1,0,IF(V38-V6<=2>15,0,_xludf.IF))))))) -> 0.4 | W39: =SUM(N39:V39) -> 0.8 | X39: =L39+W39 -> 2.4
A40: Tim | B40: Gross Score | C40: 4 | D40: 5 | E40: 4 | F40: 5 | G40: 6 | H40: 7 | I40: 4 | J40: 5 | K40: 5 | L40: =SUM(C40:K40) -> 45 | M40: Gross Score | N40: 5 | O40: 4 | P40: 3 | Q40: 4 | R40: 6 | S40: 6 | T40: 4 | U40: 5 | V40: 6 | W40: =SUM(N40:V40) -> 43 | X40: =L40+W40 -> 88
A41: 0 | B41: Handicap | L41: =SUM(C41:K41) -> 0 | M41: Handicap | W41: =SUM(N41:V41) -> 0 | X41: =L41+W41 -> 0
...

Sheet Total Points
B1: Team Blue | F1: Team White | J1: Team Green | N1: Team Black | R1: Team Orange
A2: 2022 Carroll Valley Invitational | B2: Tim | C2: Gunter | D2: Tom K | E2: Uncle Joe | F2: Eli | G2: Matt | H2: Dan | I2: Tommy | J2: Ben | K2: Andrew | L2: Tbone | M2: Rocko | N2: Oaks | O2: Frazier | P2: Vince | Q2: Uncle Mike | R2: Tophe | S2: Pete | T2: Jimmy | U2: Harvey
A3: Golf Points
A4: Closest to the Pin (1 points each) | B4: 2 | E4: 4 | F4: 1 | H4: 1 | I4: 2 | J4: 3 | K4: 1 | L4: 1 | R4: 1 | S4: 1 | T4: 1 | U4: 1
A5: Long Drive (1 points each) | F5: 1 | G5: 1 | Q5: 2 | R5: 1 | T5: 1
A6: Chip or Putt In - Fringe Doesn’t Count (2 Points) - 2 Club lengths if on Fairway. | C6: 2 | F6: 2 | G6: 2 | H6: 2 | O6: 2 | S6: 2 | T6: 2
A7: Pink Ball Challenge (2 Pts per person each round, 2 total) Tie = Pink Ball Score | C7: 2 | E7: 2 | G7: 2 | I7: 2 | L7: 2 | M7: 2 | P7: 2 | Q7: 2
A8: Best Ball Competition Days 1 & 2 w/ Cart Partner (9,8,7,6,5,4,3,2,1,0) | B8: 13 | C8: 16 | D8: 6 | E8: 9 | F8: 11 | G8: 8 | H8: 14 | I8: 11 | J8: 16 | K8: 9 | L8: 12 | M8: 5 | N8: 6 | O8: 3 | P8: 8 | Q8: 5 | R8: 6 | S8: 9 | T8: 5 | U8: 8
A9: Friday Match Play | B9: 5 | C9: 0 | D9: 1.25 | E9: 5 | F9: 0 | G9: 2.5 | H9: 1.25 | I9: 0 | J9: 0 | K9: 2.5 | L9: 5 | M9: 0 | N9: 2.5 | O9: 2.5 | P9: 5 | Q9: 5 | R9: 5 | S9: 5 | T9: 5 | U9: 5
A13: Saturday Golf - Double Eagles (3), Eagles (1.5) Birdies (.8), Pars (.4) | B13: =Golf!X133 -> 4 | C13: =Golf!X137 -> 3.2 | D13: =Golf!X141 -> 1.6 | E13: =Golf!X145 -> 5.9 | F13: =Golf!X101 -> 4.4 | G13: =Golf!X105 -> 3.2 | H13: =Golf!X109 -> 1.6 | I13: =Golf!X113 -> 2 | J13: =Golf!X149 -> 2.8 | K13: =Golf!X153 -> 4 | L13: =Golf!X157 -> 4.3 | M13: =Golf!X161 -> 0.8 | N13: =Golf!X117 -> 3.5 | O13: =Golf!X121 -> 3.6 | P13: =Golf!X125 -> 3.2 | Q13: =Golf!X129 -> 1.2 | R13: =Golf!X165 -> 2.4 | S13: =Golf!X169 -> 2 | T13: =Golf!X173 -> 2.4 | U13: =Golf!X177 -> 5.1
A14: Friday Golf - Double Eagles (3), Eagles (1.5) Birdies (.8), Pars (.4) | B14: =Golf!X43 -> 2.4 | C14: =Golf!X47 -> 4.8 | D14: =Golf!X51 -> 3.2 | E14: =Golf!X55 -> 3.6 | F14: =Golf!X11 -> 4.4 | G14: =Golf!X15 -> 3.2 | H14: =Golf!X19 -> 4.4 | I14: =Golf!X23 -> 6 | J14: =Golf!X59 -> 4.4 | K14: =Golf!X63 -> 3.6 | L14: =Golf!X67 -> 3.6 | M14: =Golf!X71 -> 2.8 | N14: =Golf!X27 -> 2.4 | O14: =Golf!X31 -> 5.5 | P14: =Golf!X35 -> 6.7 | Q14: =Golf!X39 -> 2.4 | R14: =Golf!X75 -> 2.7 | S14: =Golf!X79 -> 4.8 | T14: =Golf!X83 -> 1.6 | U14: =Golf!X87 -> 2.4
A15: Saturday Golf - Four-Man Captains Choice (3,2,1,.5 0 for each 9 and overall) | B15: 8 | C15: 8 | D15: 8 | E15: 8 | F15: 0 | G15: 0 | H15: 0 | I15: 0 | J15: 4 | K15: 4 | L15: 4 | M15: 4 | N15: 6 | O15: 6 | P15: 6 | Q15: 6 | R15: 1.5 | S15: 1.5 | T15: 1.5 | U15: 1.5
A16: Sunday Golf - Two-Man Scramble Team Win (7,6,5,4,3,2,1,0) | B16: 4 | C16: 6 | D16: 6 | E16: 4 | F16: 3 | I16: 3 | J16: 7 | K16: 8 | L16: 8 | M16: 7 | N16: 2 | O16: 5 | P16: 4 | Q16: 2 | R16: 9 | S16: 1 | T16: 1 | U16: 9
A17: Hole in One and longest putt (8 pts regular cup, 5 pts big cup, 2 pts long putt)
A18: Extra-Curricular Points
A19: Poker Friday Heads Up (4,3,2,1 Points)-No for 2019
A20: Alternate Hand Poker Friday (3, 1.5 points)-No for 2019
A21: Sand Bag Toss (3, 1.5 points)
A22: Kan Jam Doubles Saturday (3, 1.5 pts)
A23: Final table Poker(5,4,3,2,1)
A24: Total Individual Points | B24: =SUM(B4:B23) -> 38.4 | C24: =SUM(C4:C23) -> 42 | D24: =SUM(D4:D23) -> 26.05 | E24: =SUM(E4:E23) -> 41.5 | F24: =SUM(F4:F23) -> 26.8 | G24: =SUM(G4:G23) -> 21.9 | H24: =SUM(H4:H23) -> 24.25 | I24: =SUM(I4:I23) -> 26 | ... U24: =SUM(U4:U23) -> 32
A25: Total Team Points | B25: =SUM(B24:E24) -> 147.95 | F25: =SUM(F24:I24) -> 98.95 | J25: =SUM(J24:M24) -> 130.8 | N25: =SUM(N24:Q24) -> 110.5 | R25: =SUM(R24:U24) -> 107.4
A27: ** Tiebreaker in Best Ball or Captains Choice is best net score on # 1 Handicap and so on

Sheet ProAM
C4: Score | D4: Strokes | E4: Net | G4: PAID
A6: Blue | B6: Tim(5) | C6: 0 | D6: 2 | E6: =SUM(C6-D6) -> -2
B7: Matt(11) | D7: 5 | E7: =SUM(C7-D7) -> -5
B8: Ben (11) | D8: 5 | E8: =SUM(C8-D8) -> -5
B9: Bob(16) | D9: 8 | E9: =SUM(C9-D9) -> -8
E10: =SUM(E6:E9) -> -20
A11: Green | B11: Joe(0) | D11: 0 | E11: =SUM(C11-D11) -> 0
B12: Pete(10) | D12: 5 | E12: =SUM(C12-D12) -> -5
B13: Jim(11) | D13: 5 | E13: =SUM(C13-D13) -> -5
B14: Pat(17) | D14: 8 | E14: =SUM(C14-D14) -> -8
E15: =SUM(E11:E14) -> -18
A16: Orange | B16: Tophe(9) | D16: 4 | E16: =SUM(C16-D16) -> -4
B17: Matt F(7) | D17: 3 | E17: =SUM(C17-D17) -> -3
B18: Dan(15) | D18: 7 | E18: =SUM(C18-D18) -> -7
B19: Harvey16) | D19: 8 | E19: =SUM(C19-D19) -> -8
E20: =SUM(E16:E19) -> -22
A21: White | B21: LJ(8) | D21: 4 | E21: =SUM(C21-D21) -> -4
B22: Tbone(11) | D22: 5 | E22: =SUM(C22-D22) -> -5
B23: Tom K(13) | D23: 6 | E23: =SUM(C23-D23) -> -6
B24: Tom W(17) | D24: 8 | E24: =SUM(C24-D24) -> -8
E25: =SUM(E21:E24) -> -23
A26: Black | B26: Matt D | D26: 5 | E26: =SUM(C26-D26) -> -5
B27: Pete | D27: 6 | E27: =SUM(C27-D27) -> -6
B28: Mr. Bob | D28: 7 | E28: =SUM(C28-D28) -> -7
B29: Dan | D29: 9 | E29: =SUM(C29-D29) -> -9
E30: =SUM(E26:E29) -> -27
